Workbook

Sheet Synthèse
A1: BATI AZUR — Prévisionnel de ventes 2027
A2: Magasin : Les Cailles, route de Saint-Ennemond, 03000 Avermes — généré le 18/07/2026
A3: Source : export du détail des ventes (caisse iPad) du 01/01/2022 au 17/07/2026 — 7 268 lignes analysées.
A5: 1. Historique et trajectoire annuelle (CA TTC) | E5: 4. Top 15 produits — CA prévisionnel 2027
A6: Année | B6: CA TTC | C6: Nature | E6: Produit | F6: CA prév. | G6: Qté prév.
A7: 2022 | B7: 38798 | C7: réel | E7: ='CA 2027'!A5 -> Ritocal 200 | F7: ='CA 2027'!BD5 -> 9160.992 | G7: ='Qté 2027'!BD5 -> 106.03
A8: 2023 | B8: 39320 | C8: réel | E8: ='CA 2027'!A6 -> Ritocal GR | F8: ='CA 2027'!BD6 -> 7427.25 | G8: ='Qté 2027'!BD6 -> 99.03
A9: 2024 | B9: 50874 | C9: réel | E9: ='CA 2027'!A7 -> Sac de sel | F9: ='CA 2027'!BD7 -> 4817.34 | G9: ='Qté 2027'!BD7 -> 267.63
A10: 2025 | B10: 75532 | C10: réel — année exceptionnelle (été très chaud) | E10: ='CA 2027'!A8 -> Tac + poudre rehausseur de tac | F10: ='CA 2027'!BD8 -> 3653.32 | G10: ='Qté 2027'!BD8 -> 192.28
A11: 2026 | B11: 41376 | C11: réel au 17/07 ; année pleine estimée ≈ 59 100 € | E11: ='CA 2027'!A9 -> chlorit sticks | F11: ='CA 2027'!BD9 -> 3022.4948 | G11: ='Qté 2027'!BD9 -> 39.01
A12: 2027 | B12: ='CA 2027'!BD197 -> 65833.107 | C12: prévisionnel — scénario central (tendance +11 %/an vs 2026 estimé) | E12: ='CA 2027'!A10 -> Acti ph minus 20 L | F12: ='CA 2027'!BD10 -> 2530.308 | G12: ='Qté 2027'!BD10 -> 66.1
E13: ='CA 2027'!A11 -> ACTI pH Minus 5Kg | F13: ='CA 2027'!BD11 -> 2364.972 | G13: ='Qté 2027'!BD11 -> 115.93
A14: 2. Scénarios 2027 (ajuster les coefficients jaunes si besoin) | E14: ='CA 2027'!A12 -> Chlore lent galet | F14: ='CA 2027'!BD12 -> 2192.311 | G14: ='Qté 2027'!BD12 -> 48.61
A15: Scénario bas (météo fraîche/pluvieuse) | B15: 0.85 | C15: =$B$12*B15 -> 55958.141 | E15: ='CA 2027'!A13 -> SOS Eau Verte 1,8Kg | F15: ='CA 2027'!BD13 -> 2148.0944 | G15: ='Qté 2027'!BD13 -> 37.19
A16: Scénario central | B16: 1 | C16: =$B$12*B16 -> 65833.107 | E16: ='CA 2027'!A14 -> Chlore choc pastille | F16: ='CA 2027'!BD14 -> 1634.1402 | G16: ='Qté 2027'!BD14 -> 45.57
A17: Scénario haut (été type 2025, canicule) | B17: 1.2 | C17: =$B$12*B17 -> 78999.729 | E17: ='CA 2027'!A15 -> Aquachek chlorine | F17: ='CA 2027'!BD15 -> 1252.104 | G17: ='Qté 2027'!BD15 -> 69.6
E18: ='CA 2027'!A16 -> Chlorit Granulé | F18: ='CA 2027'!BD16 -> 1180.8 | G18: ='Qté 2027'!BD16 -> 19.68
A19: 3. CA prévisionnel 2027 par mois (TTC) | E19: ='CA 2027'!A17 -> Phos Out 3XL | F19: ='CA 2027'!BD17 -> 1157.5572 | G19: ='Qté 2027'!BD17 -> 30.43
A20: Mois | B20: CA prév. | C20: Semaines | E20: ='CA 2027'!A18 -> ACTI Winter Pro | F20: ='CA 2027'!BD18 -> 973.4256 | G20: ='Qté 2027'!BD18 -> 42.92
A21: Janvier | B21: =SUM('CA 2027'!D197:G197) -> 100.509 | C21: S01 à S04 | E21: ='CA 2027'!A19 -> Chlore liquide cl 48 | F21: ='CA 2027'!BD19 -> 808.272 | G21: ='Qté 2027'!BD19 -> 18.71
A22: Février | B22: =SUM('CA 2027'!H197:K197) -> 152.3008 | C22: S05 à S08
A23: Mars | B23: =SUM('CA 2027'!L197:P197) -> 1309.6871 | C23: S09 à S13
A24: Avril | B24: =SUM('CA 2027'!Q197:T197) -> 5798.4478 | C24: S14 à S17 | E24: 5. Répartition par catégorie (CA prév. 2027)
A25: Mai | B25: =SUM('CA 2027'!U197:Y197) -> 15745.266 | C25: S18 à S22 | E25: Catégorie | F25: CA prév.
A26: Juin | B26: =SUM('CA 2027'!Z197:AC197) -> 14891.394 | C26: S23 à S26 | E26: Chimie terrain | F26: =SUMIF('CA 2027'!$B$5:$B$196,E26,'CA 2027'!$BD$5:$BD$196) -> 117.1196
A27: Juillet | B27: =SUM('CA 2027'!AD197:AG197) -> 13258.012 | C27: S27 à S30 | E27: Entretien | F27: =SUMIF('CA 2027'!$B$5:$B$196,E27,'CA 2027'!$BD$5:$BD$196) -> 4086.9422
A28: Août | B28: =SUM('CA 2027'!AH197:AL197) -> 8636.4826 | C28: S31 à S35 | E28: Hivernage | F28: =SUMIF('CA 2027'!$B$5:$B$196,E28,'CA 2027'!$BD$5:$BD$196) -> 1001.3118
A29: Septembre | B29: =SUM('CA 2027'!AM197:AP197) -> 3239.3237 | C29: S36 à S39 | E29: Hydrapro | F29: =SUMIF('CA 2027'!$B$5:$B$196,E29,'CA 2027'!$BD$5:$BD$196) -> 4599.1925
A30: Octobre | B30: =SUM('CA 2027'!AQ197:AT197) -> 1574.4255 | C30: S40 à S43 | E30: Loisir | F30: =SUMIF('CA 2027'!$B$5:$B$196,E30,'CA 2027'!$BD$5:$BD$196) -> 14.6964
A31: Novembre | B31: =SUM('CA 2027'!AU197:AY197) -> 916.9998 | C31: S44 à S48 | E31: Materiel | F31: =SUMIF('CA 2027'!$B$5:$B$196,E31,'CA 2027'!$BD$5:$BD$196) -> 7459.1084
A32: Décembre | B32: =SUM('CA 2027'!AZ197:BC197) -> 210.2589 | C32: S49 à S52 | E32: Non catégorisé | F32: =SUMIF('CA 2027'!$B$5:$B$196,E32,'CA 2027'!$BD$5:$BD$196) -> 418.0428
A33: TOTAL | B33: =SUM(B21:B32) -> 65833.107 | E33: Piscimar | F33: =SUMIF('CA 2027'!$B$5:$B$196,E33,'CA 2027'!$BD$5:$BD$196) -> 24373.715
E34: Pièces détachées | F34: =SUMIF('CA 2027'!$B$5:$B$196,E34,'CA 2027'!$BD$5:$BD$196) -> 360.1644
E35: Plomberie | F35: =SUMIF('CA 2027'!$B$5:$B$196,E35,'CA 2027'!$BD$5:$BD$196) -> 202.5235
A36: Légende : texte bleu = cellule modifiable (prix unitaires en feuille 'CA 2027', coefficients de scénario ci-dessus) ; texte vert = lien vers une autre feuille ; texte noir = formule. | E36: Robot | F36: =SUMIF('CA 2027'!$B$5:$B$196,E36,'CA 2027'!$BD$5:$BD$196) -> 488.392
A37: Détail de la méthode, hypothèses et volet météo : voir feuille 'Méthode et météo'. | E37: Service | F37: =SUMIF('CA 2027'!$B$5:$B$196,E37,'CA 2027'!$BD$5:$BD$196) -> 33.9
E38: chimie | F38: =SUMIF('CA 2027'!$B$5:$B$196,E38,'CA 2027'!$BD$5:$BD$196) -> 22677.999

Sheet Qté 2027
A1: Prévisionnel 2027 — Quantités vendues par produit et par semaine (scénario central)
A3: Produit | B3: Catégorie | C3: Unité | D3: S01 | E3: S02 | F3: S03 | G3: S04 | H3: S05 | I3: S06 | J3: S07 | K3: S08 | L3: S09 | M3: S10 | N3: S11 | O3: S12 | P3: S13 | Q3: S14 | R3: S15 | S3: S16 | T3: S17 | U3: S18 | V3: S19 | W3: S20 | X3: S21 | Y3: S22 | Z3: S23 | AA3: S24 | AB3: S25 | AC3: S26 | AD3: S27 | AE3: S28 | AF3: S29 | AG3: S30 | AH3: S31 | AI3: S32 | AJ3: S33 | AK3: S34 | AL3: S35 | AM3: S36 | AN3: S37 | AO3: S38 | AP3: S39 | AQ3: S40 | AR3: S41 | AS3: S42 | AT3: S43 | AU3: S44 | AV3: S45 | AW3: S46 | AX3: S47 | AY3: S48 | AZ3: S49 | BA3: S50 | BB3: S51 | BC3: S52 | BD3: Total 2027
A4: (semaines ISO 2027 ; S01 débute le lundi 04/01/2027) | D4: du 04/01 | E4: du 11/01 | F4: du 18/01 | G4: du 25/01 | H4: du 01/02 | I4: du 08/02 | J4: du 15/02 | K4: du 22/02 | L4: du 01/03 | M4: du 08/03 | N4: du 15/03 | O4: du 22/03 | P4: du 29/03 | Q4: du 05/04 | R4: du 12/04 | S4: du 19/04 | T4: du 26/04 | U4: du 03/05 | V4: du 10/05 | W4: du 17/05 | X4: du 24/05 | Y4: du 31/05 | Z4: du 07/06 | AA4: du 14/06 | AB4: du 21/06 | AC4: du 28/06 | AD4: du 05/07 | AE4: du 12/07 | AF4: du 19/07 | AG4: du 26/07 | AH4: du 02/08 | AI4: du 09/08 | AJ4: du 16/08 | AK4: du 23/08 | AL4: du 30/08 | AM4: du 06/09 | AN4: du 13/09 | AO4: du 20/09 | AP4: du 27/09 | AQ4: du 04/10 | AR4: du 11/10 | AS4: du 18/10 | AT4: du 25/10 | AU4: du 01/11 | AV4: du 08/11 | AW4: du 15/11 | AX4: du 22/11 | AY4: du 29/11 | AZ4: du 06/12 | BA4: du 13/12 | BB4: du 20/12 | BC4: du 27/12
A5: Ritocal 200 | B5: Piscimar | C5: pce | D5: 0 | E5: 0 | F5: 0 | G5: 0 | H5: 0 | I5: 0 | J5: 0.08 | K5: 0.19 | L5: 0.23 | M5: 0.36 | N5: 0.45 | O5: 0.24 | P5: 0.23 | Q5: 0.8 | R5: 1.54 | S5: 1.95 | T5: 2.44 | U5: 3.19 | V5: 3.66 | W5: 4.14 | X5: 5.27 | Y5: 5.57 | Z5: 3.92 | AA5: 3.31 | AB5: 5.71 | AC5: 8.17 | AD5: 8.4 | AE5: 8.15 | AF5: 6.89 | AG5: 4.4 | AH5: 4.79 | AI5: 6.61 | AJ5: 5.15 | AK5: 2.21 | AL5: 1.84 | AM5: 2.34 | AN5: 1.3 | AO5: 0.35 | AP5: 0.23 | AQ5: 0.32 | AR5: 0.4 | AS5: 0.28 | AT5: 0.17 | AU5: 0.25 | AV5: 0.33 | AW5: 0.17 | AX5: 0 | AY5: 0 | AZ5: 0 | BA5: 0 | BB5: 0 | BC5: 0 | BD5: =SUM(D5:BC5) -> 106.03
A6: Ritocal GR | B6: Piscimar | C6: pce | D6: 0 | E6: 0 | F6: 0 | G6: 0 | H6: 0 | I6: 0 | J6: 0 | K6: 0 | L6: 0 | M6: 0.27 | N6: 0.6 | O6: 0.63 | P6: 0.72 | Q6: 1.39 | R6: 2.75 | S6: 3.38 | T6: 3.11 | U6: 3.22 | V6: 3.67 | W6: 4.84 | X6: 6.08 | Y6: 5.8 | Z6: 5.07 | AA6: 5.86 | AB6: 7.9 | AC6: 9.13 | AD6: 7.99 | AE6: 5.16 | AF6: 2.51 | AG6: 1.51 | AH6: 1.86 | AI6: 1.96 | AJ6: 1.56 | AK6: 1.21 | AL6: 1.94 | AM6: 2.53 | AN6: 1.64 | AO6: 1.03 | AP6: 0.68 | AQ6: 0.22 | AR6: 0.27 | AS6: 0.63 | AT6: 0.75 | AU6: 0.5 | AV6: 0.25 | AW6: 0.08 | AX6: 0 | AY6: 0.08 | AZ6: 0.17 | BA6: 0.08 | BB6: 0 | BC6: 0 | BD6: =SUM(D6:BC6) -> 99.03
A7: Sac de sel | B7: Materiel | C7: pce | D7: 0 | E7: 0 | F7: 0 | G7: 0 | H7: 0 | I7: 0 | J7: 0 | K7: 0 | L7: 0.09 | M7: 0.86 | N7: 2.02 | O7: 2.8 | P7: 3.51 | Q7: 5.81 | R7: 11.55 | S7: 17.04 | T7: 20.16 | U7: 22.79 | V7: 24.33 | W7: 24.62 | X7: 24.82 | Y7: 22.04 | Z7: 13.43 | AA7: 8.98 | AB7: 11.77 | AC7: 12.44 | AD7: 11.27 | AE7: 9.54 | AF7: 6.21 | AG7: 3.94 | AH7: 2.82 | AI7: 1.96 | AJ7: 0.83 | AK7: 0.25 | AL7: 0.75 | AM7: 0.75 | AN7: 0.25 | AO7: 0 | AP7: 0 | AQ7: 0 | AR7: 0 | AS7: 0 | AT7: 0 | AU7: 0 | AV7: 0 | AW7: 0 | AX7: 0 | AY7: 0 | AZ7: 0 | BA7: 0 | BB7: 0 | BC7: 0 | BD7: =SUM(D7:BC7) -> 267.63
A8: Tac + poudre rehausseur de tac | B8: chimie | C8: pce | D8: 0 | E8: 0 | F8: 0 | G8: 0 | H8: 0 | I8: 0 | J8: 0.09 | K8: 0.35 | L8: 0.72 | M8: 0.81 | N8: 1.01 | O8: 1.84 | P8: 2.02 | Q8: 2.03 | R8: 4.05 | S8: 7.1 | T8: 9.3 | U8: 9.21 | V8: 8.88 | W8: 13.5 | X8: 17.59 | Y8: 14.24 | Z8: 10.08 | AA8: 10.97 | AB8: 13.2 | AC8: 12.38 | AD8: 9.54 | AE8: 6.54 | AF8: 4 | AG8: 2.77 | AH8: 3.56 | AI8: 4.74 | AJ8: 3.77 | AK8: 1.94 | AL8: 2.28 | AM8: 3.21 | AN8: 1.64 | AO8: 0.53 | AP8: 1.06 | AQ8: 1.31 | AR8: 1.31 | AS8: 0.78 | AT8: 0.5 | AU8: 0.58 | AV8: 0.65 | AW8: 0.88 | AX8: 0.73 | AY8: 0.42 | AZ8: 0.17 | BA8: 0 | BB8: 0 | BC8: 0 | BD8: =SUM(D8:BC8) -> 192.28
A9: chlorit sticks | B9: chimie | C9: pce | D9: 0 | E9: 0 | F9: 0 | G9: 0 | H9: 0 | I9: 0 | J9: 0 | K9: 0 | L9: 0.06 | M9: 0.11 | N9: 0.06 | O9: 0 | P9: 0.09 | Q9: 0.33 | R9: 0.85 | S9: 1.16 | T9: 0.89 | U9: 0.82 | V9: 1.04 | W9: 1.25 | X9: 1.75 | Y9: 2.59 | Z9: 2.86 | AA9: 2.59 | AB9: 2.89 | AC9: 3.6 | AD9: 3.5 | AE9: 2.22 | AF9: 1.11 | AG9: 0.58 | AH9: 0.65 | AI9: 1.08 | AJ9: 0.8 | AK9: 0.37 | AL9: 0.7 | AM9: 0.9 | AN9: 0.48 | AO9: 0.7 | AP9: 1.05 | AQ9: 0.58 | AR9: 0.32 | AS9: 0.37 | AT9: 0.25 | AU9: 0.08 | AV9: 0 | AW9: 0 | AX9: 0 | AY9: 0.08 | AZ9: 0.17 | BA9: 0.08 | BB9: 0 | BC9: 0 | BD9: =SUM(D9:BC9) -> 39.01
A10: Acti ph minus 20 L | B10: chimie | C10: pce | D10: 0 | E10: 0 | F10: 0 | G10: 0 | H10: 0 | I10: 0 | J10: 0 | K10: 0 | L10: 0 | M10: 0 | N10: 0.18 | O10: 0.52 | P10: 0.55 | Q10: 0.33 | R10: 0.51 | S10: 1.12 | T10: 1.29 | U10: 1.27 | V10: 2.6 | W10: 4.2 | X10: 4.23 | Y10: 3.56 | Z10: 3.21 | AA10: 3.75 | AB10: 4.51 | AC10: 4.32 | AD10: 3.97 | AE10: 3.85 | AF10: 3.64 | AG10: 3.51 | AH10: 3.17 | AI10: 2.23 | AJ10: 0.96 | AK10: 0.17 | AL10: 0.52 | AM10: 1.11 | AN10: 1 | AO10: 0.83 | AP10: 0.83 | AQ10: 1.11 | AR10: 1.15 | AS10: 0.43 | AT10: 0 | AU10: 0.08 | AV10: 0.17 | AW10: 0.08 | AX10: 0.17 | AY10: 0.33 | AZ10: 0.17 | BA10: 0.12 | BB10: 0.23 | BC10: 0.12 | BD10: =SUM(D10:BC10) -> 66.1
A11: ACTI pH Minus 5Kg | B11: chimie | C11: pce | D11: 0 | E11: 0 | F11: 0 | G11: 0 | H11: 0 | I11: 0 | J11: 0 | K11: 0.02 | L11: 0.05 | M11: 0.17 | N11: 0.6 | O11: 1.08 | P11: 1.25 | Q11: 1.88 | R11: 3.1 | S11: 3.45 | T11: 3.91 | U11: 4.8 | V11: 4.73 | W11: 4.99 | X11: 5.11 | Y11: 4.02 | Z11: 4.51 | AA11: 6.78 | AB11: 7.63 | AC11: 6.94 | AD11: 6.49 | AE11: 6.64 | AF11: 6.13 | AG11: 5.12 | AH11: 5.3 | AI11: 5.22 | AJ11: 3.04 | AK11: 1.33 | AL11: 1.71 | AM11: 1.76 | AN11: 0.93 | AO11: 0.81 | AP11: 0.91 | AQ11: 0.63 | AR11: 0.61 | AS11: 0.61 | AT11: 0.7 | AU11: 0.9 | AV11: 0.61 | AW11: 0.33 | AX11: 0.33 | AY11: 0.25 | AZ11: 0.08 | BA11: 0.12 | BB11: 0.23 | BC11: 0.12 | BD11: =SUM(D11:BC11) -> 115.93
A12: Chlore lent galet | B12: Hydrapro | C12: pce | D12: 0 | E12: 0 | F12: 0 | G12: 0 | H12: 0 | I12: 0 | J12: 0 | K12: 0 | L12: 0 | M12: 0 | N12: 0.2 | O12: 0.41 | P12: 0.4 | Q12: 0.9 | R12: 1.5 | S12: 1.06 | T12: 0.44 | U12: 0.55 | V12: 0.76 | W12: 1.16 | X12: 2.03 | Y12: 2.03 | Z12: 1.71 | AA12: 2.44 | AB12: 3.72 | AC12: 5.02 | AD12: 5.38 | AE12: 4.15 | AF12: 2.61 | AG12: 1.79 | AH12: 1.6 | AI12: 2.09 | AJ12: 2.21 | AK12: 1.45 | AL12: 0.96 | AM12: 0.61 | AN12: 0.4 | AO12: 0.47 | AP12: 0.23 | AQ12: 0 | AR12: 0 | AS12: 0 | AT12: 0 | AU12: 0 | AV12: 0 | AW12: 0 | AX12: 0.08 | AY12: 0.17 | AZ12: 0.08 | BA12: 0 | BB12: 0 | BC12: 0 | BD12: =SUM(D12:BC12) -> 48.61
A13: SOS Eau Verte 1,8Kg | B13: Piscimar | C13: pce | D13: 0 | E13: 0 | F13: 0 | G13: 0 | H13: 0 | I13: 0 | J13: 0 | K13: 0 | L13: 0 | M13: 0 | N13: 0.06 | O13: 0.28 | P13: 0.4 | Q13: 0.64 | R13: 1.32 | S13: 1.62 | T13: 1.43 | U13: 1.01 | V13: 0.66 | W13: 0.98 | X13: 1.81 | Y13: 2.17 | Z13: 1.84 | AA13: 2.06 | AB13: 2.21 | AC13: 1.94 | AD13: 2.33 | AE13: 2.54 | AF13: 2.1 | AG13: 1.81 | AH13: 1.94 | AI13: 1.6 | AJ13: 0.6 | AK13: 0.32 | AL13: 0.73 | AM13: 0.66 | AN13: 0.2 | AO13: 0 | AP13: 0 | AQ13: 0.08 | AR13: 0.33 | AS13: 0.42 | AT13: 0.28 | AU13: 0.32 | AV13: 0.32 | AW13: 0.15 | AX13: 0.03 | AY13: 0 | AZ13: 0 | BA13: 0 | BB13: 0 | BC13: 0 | BD13: =SUM(D13:BC13) -> 37.19
A14: Chlore choc pastille | B14: chimie | C14: pce | D14: 0 | E14: 0 | F14: 0.06 | G14: 0.11 | H14: 0.06 | I14: 0 | J14: 0 | K14: 0 | L14: 0 | M14: 0 | N14: 0.36 | O14: 0.76 | P14: 0.63 | Q14: 0.52 | R14: 0.68 | S14: 0.9 | T14: 1.02 | U14: 1.21 | V14: 1.48 | W14: 1.75 | X14: 2.2 | Y14: 2.37 | Z14: 1.94 | AA14: 1.66 | AB14: 2.12 | AC14: 3.01 | AD14: 3.42 | AE14: 3.03 | AF14: 2.43 | AG14: 1.73 | AH14: 1.56 | AI14: 2.34 | AJ14: 2.31 | AK14: 1.38 | AL14: 1.08 | AM14: 0.88 | AN14: 0.4 | AO14: 0.13 | AP14: 0.12 | AQ14: 0.13 | AR14: 0.25 | AS14: 0.45 | AT14: 0.33 | AU14: 0.12 | AV14: 0.07 | AW14: 0.07 | AX14: 0.15 | AY14: 0.23 | AZ14: 0.12 | BA14: 0 | BB14: 0 | BC14: 0 | BD14: =SUM(D14:BC14) -> 45.57
A15: Aquachek chlorine | B15: Entretien | C15: pce | D15: 0 | E15: 0 | F15: 0 | G15: 0 | H15: 0 | I15: 0 | J15: 0 | K15: 0 | L15: 0 | M15: 0 | N15: 0.09 | O15: 0.29 | P15: 0.56 | Q15: 0.88 | R15: 1.05 | S15: 1.1 | T15: 1.81 | U15: 2.73 | V15: 3.01 | W15: 3.24 | X15: 3.41 | Y15: 3.47 | Z15: 3.28 | AA15: 3.36 | AB15: 4.14 | AC15: 5.21 | AD15: 6.07 | AE15: 5.11 | AF15: 3.15 | AG15: 2.36 | AH15: 2.82 | AI15: 3.54 | AJ15: 3.11 | AK15: 1.64 | AL15: 1.01 | AM15: 1 | AN15: 0.63 | AO15: 0.2 | AP15: 0.08 | AQ15: 0.17 | AR15: 0.17 | AS15: 0.25 | AT15: 0.25 | AU15: 0.08 | AV15: 0.08 | AW15: 0.17 | AX15: 0.08 | AY15: 0 | AZ15: 0 | BA15: 0 | BB15: 0 | BC15: 0 | BD15: =SUM(D15:BC15) -> 69.6
A16: Chlorit Granulé | B16: chimie | C16: pce | D16: 0 | E16: 0 | F16: 0 | G16: 0 | H16: 0 | I16: 0 | J16: 0 | K16: 0 | L16: 0 | M16: 0 | N16: 0 | O16: 0 | P16: 0 | Q16: 0.08 | R16: 0.35 | S16: 0.46 | T16: 0.35 | U16: 0.51 | V16: 1.11 | W16: 1.47 | X16: 0.92 | Y16: 0.59 | Z16: 0.87 | AA16: 0.72 | AB16: 0.43 | AC16: 0.78 | AD16: 1.2 | AE16: 1.14 | AF16: 1.38 | AG16: 1.3 | AH16: 0.65 | AI16: 0.65 | AJ16: 0.7 | AK16: 0.5 | AL16: 0.86 | AM16: 1.06 | AN16: 0.53 | AO16: 0.08 | AP16: 0 | AQ16: 0.08 | AR16: 0.17 | AS16: 0.08 | AT16: 0 | AU16: 0 | AV16: 0 | AW16: 0 | AX16: 0.08 | AY16: 0.17 | AZ16: 0.08 | BA16: 0.08 | BB16: 0.17 | BC16: 0.08 | BD16: =SUM(D16:BC16) -> 19.68
... A196: Embout à Coller PVC ∅50 | B196: Plomberie | C196: pce | D196: 0 | E196: 0 | F196: 0 | G196: 0.05 | H196: 0.09 | I196: 0.05 | J196: 0 | K196: 0 | L196: 0 | M196: 0 | N196: 0 | O196: 0 | P196: 0 | Q196: 0.03 | R196: 0.07 | S196: 0.03 | T196: 0 | U196: 0 | V196: 0.06 | W196: 0.11 | X196: 0.06 | Y196: 0 | Z196: 0 | AA196: 0 | AB196: 0 | AC196: 0 | AD196: 0 | AE196: 0 | AF196: 0 | AG196: 0 | AH196: 0 | AI196: 0 | AJ196: 0 | AK196: 0 | AL196: 0 | AM196: 0 | AN196: 0 | AO196: 0 | AP196: 0 | AQ196: 0 | AR196: 0 | AS196: 0 | AT196: 0 | AU196: 0 | AV196: 0 | AW196: 0 | AX196: 0 | AY196: 0 | AZ196: 0 | BA196: 0 | BB196: 0 | BC196: 0 | BD196: =SUM(D196:BC196) -> 0.55
A197: TOTAL articles / semaine | D197: =SUM(D5:D196) -> 0.72 | E197: =SUM(E5:E196) -> 1.26 | F197: =SUM(F5:F196) -> 0.74 | G197: =SUM(G5:G196) -> 0.62 | H197: =SUM(H5:H196) -> 1.09 | I197: =SUM(I5:I196) -> 1.17 | J197: =SUM(J5:J196) -> 1.17 | K197: =SUM(K5:K196) -> 1.23 | ... BC197: =SUM(BC5:BC196) -> 0.64 | BD197: =SUM(D197:BC197) -> 2108.27

Sheet CA 2027
A1: Prévisionnel 2027 — Chiffre d'affaires TTC par produit et par semaine (scénario central)
A2: CA = quantité (feuille 'Qté 2027') × prix unitaire TTC (colonne C, modifiable — texte bleu).
A3: Produit | B3: Catégorie | C3: Prix unit. TTC | D3: S01 | E3: S02 | F3: S03 | G3: S04 | H3: S05 | I3: S06 | J3: S07 | K3: S08 | L3: S09 | M3: S10 | N3: S11 | O3: S12 | P3: S13 | Q3: S14 | R3: S15 | S3: S16 | T3: S17 | U3: S18 | V3: S19 | W3: S20 | X3: S21 | Y3: S22 | Z3: S23 | AA3: S24 | AB3: S25 | AC3: S26 | AD3: S27 | AE3: S28 | AF3: S29 | AG3: S30 | AH3: S31 | AI3: S32 | AJ3: S33 | AK3: S34 | AL3: S35 | AM3: S36 | AN3: S37 | AO3: S38 | AP3: S39 | AQ3: S40 | AR3: S41 | AS3: S42 | AT3: S43 | AU3: S44 | AV3: S45 | AW3: S46 | AX3: S47 | AY3: S48 | AZ3: S49 | BA3: S50 | BB3: S51 | BC3: S52 | BD3: Total 2027
D4: du 04/01 | E4: du 11/01 | F4: du 18/01 | G4: du 25/01 | H4: du 01/02 | I4: du 08/02 | J4: du 15/02 | K4: du 22/02 | L4: du 01/03 | M4: du 08/03 | N4: du 15/03 | O4: du 22/03 | P4: du 29/03 | Q4: du 05/04 | R4: du 12/04 | S4: du 19/04 | T4: du 26/04 | U4: du 03/05 | V4: du 10/05 | W4: du 17/05 | X4: du 24/05 | Y4: du 31/05 | Z4: du 07/06 | AA4: du 14/06 | AB4: du 21/06 | AC4: du 28/06 | AD4: du 05/07 | AE4: du 12/07 | AF4: du 19/07 | AG4: du 26/07 | AH4: du 02/08 | AI4: du 09/08 | AJ4: du 16/08 | AK4: du 23/08 | AL4: du 30/08 | AM4: du 06/09 | AN4: du 13/09 | AO4: du 20/09 | AP4: du 27/09 | AQ4: du 04/10 | AR4: du 11/10 | AS4: du 18/10 | AT4: du 25/10 | AU4: du 01/11 | AV4: du 08/11 | AW4: du 15/11 | AX4: du 22/11 | AY4: du 29/11 | AZ4: du 06/12 | BA4: du 13/12 | BB4: du 20/12 | BC4: du 27/12
A5: Ritocal 200 | B5: Piscimar | C5: 86.4 | D5: ='Qté 2027'!D5*$C5 -> 0 | E5: ='Qté 2027'!E5*$C5 -> 0 | F5: ='Qté 2027'!F5*$C5 -> 0 | G5: ='Qté 2027'!G5*$C5 -> 0 | H5: ='Qté 2027'!H5*$C5 -> 0 | I5: ='Qté 2027'!I5*$C5 -> 0 | J5: ='Qté 2027'!J5*$C5 -> 6.912 | K5: ='Qté 2027'!K5*$C5 -> 16.416 | ... BC5: ='Qté 2027'!BC5*$C5 -> 0 | BD5: =SUM(D5:BC5) -> 9160.992
A6: Ritocal GR | B6: Piscimar | C6: 75 | D6: ='Qté 2027'!D6*$C6 -> 0 | E6: ='Qté 2027'!E6*$C6 -> 0 | F6: ='Qté 2027'!F6*$C6 -> 0 | G6: ='Qté 2027'!G6*$C6 -> 0 | H6: ='Qté 2027'!H6*$C6 -> 0 | I6: ='Qté 2027'!I6*$C6 -> 0 | J6: ='Qté 2027'!J6*$C6 -> 0 | K6: ='Qté 2027'!K6*$C6 -> 0 | ... BC6: ='Qté 2027'!BC6*$C6 -> 0 | BD6: =SUM(D6:BC6) -> 7427.25
A7: Sac de sel | B7: Materiel | C7: 18 | D7: ='Qté 2027'!D7*$C7 -> 0 | E7: ='Qté 2027'!E7*$C7 -> 0 | F7: ='Qté 2027'!F7*$C7 -> 0 | G7: ='Qté 2027'!G7*$C7 -> 0 | H7: ='Qté 2027'!H7*$C7 -> 0 | I7: ='Qté 2027'!I7*$C7 -> 0 | J7: ='Qté 2027'!J7*$C7 -> 0 | K7: ='Qté 2027'!K7*$C7 -> 0 | ... BC7: ='Qté 2027'!BC7*$C7 -> 0 | BD7: =SUM(D7:BC7) -> 4817.34
A8: Tac + poudre rehausseur de tac | B8: chimie | C8: 19 | D8: ='Qté 2027'!D8*$C8 -> 0 | E8: ='Qté 2027'!E8*$C8 -> 0 | F8: ='Qté 2027'!F8*$C8 -> 0 | G8: ='Qté 2027'!G8*$C8 -> 0 | H8: ='Qté 2027'!H8*$C8 -> 0 | I8: ='Qté 2027'!I8*$C8 -> 0 | J8: ='Qté 2027'!J8*$C8 -> 1.71 | K8: ='Qté 2027'!K8*$C8 -> 6.65 | ... BC8: ='Qté 2027'!BC8*$C8 -> 0 | BD8: =SUM(D8:BC8) -> 3653.32
A9: chlorit sticks | B9: chimie | C9: 77.48 | D9: ='Qté 2027'!D9*$C9 -> 0 | E9: ='Qté 2027'!E9*$C9 -> 0 | F9: ='Qté 2027'!F9*$C9 -> 0 | G9: ='Qté 2027'!G9*$C9 -> 0 | H9: ='Qté 2027'!H9*$C9 -> 0 | I9: ='Qté 2027'!I9*$C9 -> 0 | J9: ='Qté 2027'!J9*$C9 -> 0 | K9: ='Qté 2027'!K9*$C9 -> 0 | ... BC9: ='Qté 2027'!BC9*$C9 -> 0 | BD9: =SUM(D9:BC9) -> 3022.4948
A10: Acti ph minus 20 L | B10: chimie | C10: 38.28 | D10: ='Qté 2027'!D10*$C10 -> 0 | E10: ='Qté 2027'!E10*$C10 -> 0 | F10: ='Qté 2027'!F10*$C10 -> 0 | G10: ='Qté 2027'!G10*$C10 -> 0 | H10: ='Qté 2027'!H10*$C10 -> 0 | I10: ='Qté 2027'!I10*$C10 -> 0 | J10: ='Qté 2027'!J10*$C10 -> 0 | K10: ='Qté 2027'!K10*$C10 -> 0 | ... BC10: ='Qté 2027'!BC10*$C10 -> 4.5936 | BD10: =SUM(D10:BC10) -> 2530.308
A11: ACTI pH Minus 5Kg | B11: chimie | C11: 20.4 | D11: ='Qté 2027'!D11*$C11 -> 0 | E11: ='Qté 2027'!E11*$C11 -> 0 | F11: ='Qté 2027'!F11*$C11 -> 0 | G11: ='Qté 2027'!G11*$C11 -> 0 | H11: ='Qté 2027'!H11*$C11 -> 0 | I11: ='Qté 2027'!I11*$C11 -> 0 | J11: ='Qté 2027'!J11*$C11 -> 0 | K11: ='Qté 2027'!K11*$C11 -> 0.408 | ... BC11: ='Qté 2027'!BC11*$C11 -> 2.448 | BD11: =SUM(D11:BC11) -> 2364.972
A12: Chlore lent galet | B12: Hydrapro | C12: 45.1 | D12: ='Qté 2027'!D12*$C12 -> 0 | E12: ='Qté 2027'!E12*$C12 -> 0 | F12: ='Qté 2027'!F12*$C12 -> 0 | G12: ='Qté 2027'!G12*$C12 -> 0 | H12: ='Qté 2027'!H12*$C12 -> 0 | I12: ='Qté 2027'!I12*$C12 -> 0 | J12: ='Qté 2027'!J12*$C12 -> 0 | K12: ='Qté 2027'!K12*$C12 -> 0 | ... BC12: ='Qté 2027'!BC12*$C12 -> 0 | BD12: =SUM(D12:BC12) -> 2192.311
A13: SOS Eau Verte 1,8Kg | B13: Piscimar | C13: 57.76 | D13: ='Qté 2027'!D13*$C13 -> 0 | E13: ='Qté 2027'!E13*$C13 -> 0 | F13: ='Qté 2027'!F13*$C13 -> 0 | G13: ='Qté 2027'!G13*$C13 -> 0 | H13: ='Qté 2027'!H13*$C13 -> 0 | I13: ='Qté 2027'!I13*$C13 -> 0 | J13: ='Qté 2027'!J13*$C13 -> 0 | K13: ='Qté 2027'!K13*$C13 -> 0 | ... BC13: ='Qté 2027'!BC13*$C13 -> 0 | BD13: =SUM(D13:BC13) -> 2148.0944
A14: Chlore choc pastille | B14: chimie | C14: 35.86 | D14: ='Qté 2027'!D14*$C14 -> 0 | E14: ='Qté 2027'!E14*$C14 -> 0 | F14: ='Qté 2027'!F14*$C14 -> 2.1516 | G14: ='Qté 2027'!G14*$C14 -> 3.9446 | H14: ='Qté 2027'!H14*$C14 -> 2.1516 | I14: ='Qté 2027'!I14*$C14 -> 0 | J14: ='Qté 2027'!J14*$C14 -> 0 | K14: ='Qté 2027'!K14*$C14 -> 0 | ... BC14: ='Qté 2027'!BC14*$C14 -> 0 | BD14: =SUM(D14:BC14) -> 1634.1402
A15: Aquachek chlorine | B15: Entretien | C15: 17.99 | D15: ='Qté 2027'!D15*$C15 -> 0 | E15: ='Qté 2027'!E15*$C15 -> 0 | F15: ='Qté 2027'!F15*$C15 -> 0 | G15: ='Qté 2027'!G15*$C15 -> 0 | H15: ='Qté 2027'!H15*$C15 -> 0 | I15: ='Qté 2027'!I15*$C15 -> 0 | J15: ='Qté 2027'!J15*$C15 -> 0 | K15: ='Qté 2027'!K15*$C15 -> 0 | ... BC15: ='Qté 2027'!BC15*$C15 -> 0 | BD15: =SUM(D15:BC15) -> 1252.104
A16: Chlorit Granulé | B16: chimie | C16: 60 | D16: ='Qté 2027'!D16*$C16 -> 0 | E16: ='Qté 2027'!E16*$C16 -> 0 | F16: ='Qté 2027'!F16*$C16 -> 0 | G16: ='Qté 2027'!G16*$C16 -> 0 | H16: ='Qté 2027'!H16*$C16 -> 0 | I16: ='Qté 2027'!I16*$C16 -> 0 | J16: ='Qté 2027'!J16*$C16 -> 0 | K16: ='Qté 2027'!K16*$C16 -> 0 | ... BC16: ='Qté 2027'!BC16*$C16 -> 4.8 | BD16: =SUM(D16:BC16) -> 1180.8
... A196: Embout à Coller PVC ∅50 | B196: Plomberie | C196: 1.76 | D196: ='Qté 2027'!D196*$C196 -> 0 | E196: ='Qté 2027'!E196*$C196 -> 0 | F196: ='Qté 2027'!F196*$C196 -> 0 | G196: ='Qté 2027'!G196*$C196 -> 0.088 | H196: ='Qté 2027'!H196*$C196 -> 0.1584 | I196: ='Qté 2027'!I196*$C196 -> 0.088 | J196: ='Qté 2027'!J196*$C196 -> 0 | K196: ='Qté 2027'!K196*$C196 -> 0 | ... BC196: ='Qté 2027'!BC196*$C196 -> 0 | BD196: =SUM(D196:BC196) -> 0.968
A197: TOTAL CA TTC / semaine | D197: =SUM(D5:D196) -> 23.2501 | E197: =SUM(E5:E196) -> 41.861 | F197: =SUM(F5:F196) -> 24.4945 | G197: =SUM(G5:G196) -> 10.9034 | H197: =SUM(H5:H196) -> 25.3132 | I197: =SUM(I5:I196) -> 41.3444 | J197: =SUM(J5:J196) -> 43.9336 | K197: =SUM(K5:K196) -> 41.7096 | ... BC197: =SUM(BC5:BC196) -> 20.9424 | BD197: =SUM(D197:BC197) -> 65833.107

Sheet Historique hebdo
A1: CA TTC hebdomadaire — historique 2022-2026 (réel) et prévisionnel 2027
A3: Semaine | B3: Début (2027) | C3: CA 2022 | D3: CA 2023 | E3: CA 2024 | F3: CA 2025 | G3: CA 2026* | H3: Prév. 2027
A4: S01 | B4: 46391 | C4: 0 | D4: 18 | E4: 0 | F4: 0 | G4: 0 | H4: ='CA 2027'!D197 -> 23.2501
A5: S02 | B5: 46398 | C5: 86 | D5: 130 | E5: 70 | F5: 133 | G5: 0 | H5: ='CA 2027'!E197 -> 41.861
A6: S03 | B6: 46405 | C6: 78 | D6: 0 | E6: 0 | F6: 0 | G6: 0 | H6: ='CA 2027'!F197 -> 24.4945
A7: S04 | B7: 46412 | C7: 0 | D7: 0 | E7: 54 | F7: 0 | G7: 0 | H7: ='CA 2027'!G197 -> 10.9034
A8: S05 | B8: 46419 | C8: 71 | D8: 0 | E8: 18 | F8: 37 | G8: 0 | H8: ='CA 2027'!H197 -> 25.3132
A9: S06 | B9: 46426 | C9: 5 | D9: 0 | E9: 0 | F9: 0 | G9: 137 | H9: ='CA 2027'!I197 -> 41.3444
A10: S07 | B10: 46433 | C10: 26 | D10: 0 | E10: 46 | F10: 72 | G10: 23 | H10: ='CA 2027'!J197 -> 43.9336
A11: S08 | B11: 46440 | C11: 34 | D11: 52 | E11: 0 | F11: 88 | G11: 19 | H11: ='CA 2027'!K197 -> 41.7096
A12: S09 | B12: 46447 | C12: 162 | D12: 83 | E12: 19 | F12: 62 | G12: 19 | H12: ='CA 2027'!L197 -> 58.6876
A13: S10 | B13: 46454 | C13: 213 | D13: 0 | E13: 126 | F13: 106 | G13: 53 | H13: ='CA 2027'!M197 -> 120.4472
A14: S11 | B14: 46461 | C14: 0 | D14: 116 | E14: 52 | F14: 70 | G14: 450 | H14: ='CA 2027'!N197 -> 258.5269
A15: S12 | B15: 46468 | C15: 222 | D15: 828 | E15: 557 | F15: 300 | G15: 320 | H15: ='CA 2027'!O197 -> 401.7977
A16: S13 | B16: 46475 | C16: 428 | D16: 375 | E16: 316 | F16: 529 | G16: 383 | H16: ='CA 2027'!P197 -> 470.2277
A17: S14 | B17: 46482 | C17: 229 | D17: 513 | E17: 820 | F17: 446 | G17: 269 | H17: ='CA 2027'!Q197 -> 760.5641
A18: S15 | B18: 46489 | C18: 1010 | D18: 413 | E18: 1596 | F18: 1778 | G18: 1145 | H18: ='CA 2027'!R197 -> 1389.2975
A19: S16 | B19: 46496 | C19: 1830 | D19: 1035 | E19: 1146 | F19: 1577 | G19: 2324 | H19: ='CA 2027'!S197 -> 1751.3822
A20: S17 | B20: 46503 | C20: 1523 | D20: 1005 | E20: 1028 | F20: 1210 | G20: 1895 | H20: ='CA 2027'!T197 -> 1897.204
A21: S18 | B21: 46510 | C21: 3340 | D21: 1467 | E21: 705 | F21: 4390 | G21: 1732 | H21: ='CA 2027'!U197 -> 2204.5882
A22: S19 | B22: 46517 | C22: 3683 | D22: 1598 | E22: 2136 | F22: 2265 | G22: 1136 | H22: ='CA 2027'!V197 -> 2571.7332
A23: S20 | B23: 46524 | C23: 3305 | D23: 1713 | E23: 2937 | F23: 4718 | G23: 1410 | H23: ='CA 2027'!W197 -> 3096.2259
A24: S21 | B24: 46531 | C24: 1270 | D24: 3129 | E24: 1468 | F24: 3058 | G24: 5304 | H24: ='CA 2027'!X197 -> 3853.8815
A25: S22 | B25: 46538 | C25: 1660 | D25: 3793 | E25: 1205 | F25: 6284 | G25: 5166 | H25: ='CA 2027'!Y197 -> 4018.8373
A26: S23 | B26: 46545 | C26: 1626 | D26: 2025 | E26: 2230 | F26: 3065 | G26: 2195 | H26: ='CA 2027'!Z197 -> 3310.4797
A27: S24 | B27: 46552 | C27: 1739 | D27: 2408 | E27: 1341 | F27: 4329 | G27: 2385 | H27: ='CA 2027'!AA197 -> 3194.7134
A28: S25 | B28: 46559 | C28: 1475 | D28: 1115 | E28: 1034 | F28: 7524 | G28: 2805 | H28: ='CA 2027'!AB197 -> 3921.5292
A29: S26 | B29: 46566 | C29: 1409 | D29: 1549 | E29: 4222 | F29: 5432 | G29: 3875 | H29: ='CA 2027'!AC197 -> 4464.6718
A30: S27 | B30: 46573 | C30: 1936 | D30: 1961 | E30: 1771 | F30: 6818 | G30: 4143 | H30: ='CA 2027'!AD197 -> 4330.6478
A31: S28 | B31: 46580 | C31: 1403 | D31: 1266 | E31: 3602 | F31: 4087 | G31: 3410 | H31: ='CA 2027'!AE197 -> 3694.114
A32: S29 | B32: 46587 | C32: 1118 | D32: 2057 | E32: 3447 | F32: 3023 | H32: ='CA 2027'!AF197 -> 2943.9954
A33: S30 | B33: 46594 | C33: 1081 | D33: 902 | E33: 2319 | F33: 1737 | H33: ='CA 2027'!AG197 -> 2289.2546
A34: S31 | B34: 46601 | C34: 2069 | D34: 845 | E34: 2806 | F34: 1658 | H34: ='CA 2027'!AH197 -> 2260.7916
A35: S32 | B35: 46608 | C35: 1351 | D35: 1690 | E35: 2182 | F35: 3298 | H35: ='CA 2027'!AI197 -> 2455.1576
A36: S33 | B36: 46615 | C36: 0 | D36: 224 | E36: 2072 | F36: 2491 | H36: ='CA 2027'!AJ197 -> 1781.3504
A37: S34 | B37: 46622 | C37: 0 | D37: 281 | E37: 81 | F37: 383 | H37: ='CA 2027'!AK197 -> 963.9796
A38: S35 | B38: 46629 | C38: 1297 | D38: 1271 | E38: 2576 | F38: 45 | H38: ='CA 2027'!AL197 -> 1175.2034
A39: S36 | B39: 46636 | C39: 697 | D39: 1774 | E39: 1793 | F39: 1503 | H39: ='CA 2027'!AM197 -> 1343.9353
A40: S37 | B40: 46643 | C40: 0 | D40: 576 | E40: 433 | F40: 343 | H40: ='CA 2027'!AN197 -> 830.1192
A41: S38 | B41: 46650 | C41: 477 | D41: 633 | E41: 289 | F41: 670 | H41: ='CA 2027'!AO197 -> 555.983
...

Sheet Méthode et météo
A1: Méthode de calcul, hypothèses et volet météorologique
A3: SOURCE DES DONNÉES
A4: • Export PDF du détail des ventes de la caisse (7 269 lignes, 01/01/2022 → 17/07/2026) fourni le 17/07/2026.
A5: • 7 268 lignes exploitées (1 ligne écartée : vente à 0 € sans quantité). Remboursements comptés en négatif.
A6: • Les libellés produits ont été harmonisés entre années (ex. « Piscimar Ritocal 200 » = « Ritocal 200 » ; 36 fusions).
A7: • Périmètre du prévisionnel : les 192 produits vendus au moins une fois depuis le 01/01/2024.
A8: Les produits sans aucune vente depuis 2024 (référencements abandonnés) sont exclus.
A10: MÉTHODE (par produit et par semaine ISO)
A11: 1. Quantités agrégées par produit × semaine ISO × année (2022 à 2026).
A12: 2. Profil hebdomadaire = moyenne pondérée par récence : 2022×0,4 · 2023×0,6 · 2024×1,0 · 2025×1,4 · 2026×1,6.
A13: Pour les semaines 29 à 52, l'année 2026 est exclue (données arrêtées au 17/07/2026).
A14: 3. Lissage sur 3 semaines glissantes (25 % / 50 % / 25 %) pour atténuer le bruit des petites séries.
... A44: (magasin historiquement fermé à cette période).
